Workbook

Sheet Sche
B1: Date | D1: Date | F1: Date | H1: Date | J1: Date | L1: ROLE/ACTIVITY | M1: PARTICIPANTS | N1: DAY | O1: HOUR | P1: PROJECT
B2: 46300 | D2: =B2+1 -> 46301 | F2: =D2+1 -> 46302 | H2: =F2+1 -> 46303 | J2: =H2+1 -> 46304
A3: 0.37152778 | B3: Connection Test | C3: 0.37152778 | D3: Connection Test | E3: 0.37152778 | F3: Connection Test | G3: 0.37152778 | H3: Connection Test | I3: 0.37152778 | J3: Connection Test | L3: Briefing & Final Findings | M3: All participants + sponsor | O3: See schedule | P3: ALL
A4: 0.375 | B4: Appraisal participants briefing | C4: 0.375 | D4: Team Planning | E4: 0.375 | F4: Team Planning | G4: 0.375 | H4: Team Planning | I4: 0.375 | J4: Team Planning | L4: Mini-Teams debrief | M4: ATMs | O4: See schedule | P4: ATM | R4: P1 | S4: P2 | T4: P3
A5: 0.38541667 | C5: 0.38541667 | E5: 0.38541667 | G5: 0.38541667 | I5: 0.38541667 | L5: EPG | M5: =participants!C2 -> Ana L. Fragoso C. | N5: =B2 -> 46300 | O5: See schedule | P5: ALL | Q5: 1
A6: 0.39583333 | B6: Review Evidence and Team Training | C6: 0.39583333 | D6: Human Resources (OT) | E6: 0.39583333 | F6: Configuration Manager (CM) | G6: 0.39583333 | H6: Findings Consolidation | I6: 0.39583333 | J6: Preliminary Findings & Performance Report Review | M6: Karen Ailine Espinoza | Q6: 1
A7: 0.40625 | C7: 0.40625 | E7: 0.40625 | G7: 0.40625 | I7: 0.40625
A8: 0.41666667 | C8: 0.41666667 | E8: 0.41666667 | G8: 0.41666667 | I8: 0.41666667 | L8: QA(Quality Assurance) | M8: =participants!C5 -> Luis Erick Rodríguez | N8: =B2 -> 46300 | O8: See schedule | P8: ALL | Q8: 1
A9: 0.42708333 | C9: 0.42708333 | E9: 0.42708333 | G9: 0.42708333 | I9: 0.42708333
A10: 0.4375 | B10: SM GOV, II | C10: 0.4375 | D10: Review Evidence and Team Training | E10: 0.4375 | F10: Review Evidence and Team Training | G10: 0.4375 | I10: 0.4375 | L10: OT | M10: =participants!C7 -> Florencia Vitale | N10: =D2 -> 46301 | O10: See schedule | P10: ALL | Q10: 1
A11: 0.44791667 | C11: 0.44791667 | E11: 0.44791667 | G11: 0.44791667 | I11: 0.44791667 | J11: Preliminary Findings
A12: 0.45833333 | C12: 0.45833333 | E12: 0.45833333 | G12: 0.45833333 | I12: 0.45833333 | L12: CM | M12: =participants!C9 -> Carlos Quintero N. | N12: =F2 -> 46302 | O12: See schedule | P12: ALL | Q12: 1
A13: 0.46875 | C13: 0.46875 | E13: 0.46875 | G13: 0.46875 | I13: 0.46875 | J13: Follow-up 2 | L13: Sr. Management | M13: =participants!C10 -> Oscar Vera | N13: =B2 -> 46300 | O13: See schedule | P13: ALL | Q13: 1
A14: 0.47916667 | B14: Break | C14: 0.47916667 | D14: PM2 (EST, PLAN, MC,) | E14: 0.47916667 | F14: FAR 02 (VV, PR,) | G14: 0.47916667 | H14: Review Findings Consolidation | I14: 0.47916667
A15: 0.48958333 | B15: EPG PAD, PCM, MPM | C15: 0.48958333 | E15: 0.48958333 | G15: 0.48958333 | I15: 0.48958333 | J15: Finalize Findings and Ratings
A16: 0.5 | C16: 0.5 | E16: 0.5 | G16: 0.5 | I16: 0.5 | L16: Requirements | M16: =participants!C13 -> Carlos Quintero N. | N16: =F2 -> 46302 | O16: See schedule | P16: P1 | R16: 0
A17: 0.51041667 | C17: 0.51041667 | E17: 0.51041667 | G17: 0.51041667 | I17: 0.51041667 | M17: =participants!C14 -> 0 | P17: P2
A18: 0.52083333 | C18: 0.52083333 | E18: 0.52083333 | G18: 0.52083333 | I18: 0.52083333 | M18: =participants!C15 -> 0 | P18: P3
A19: 0.53125 | B19: Break | C19: 0.53125 | E19: 0.53125 | F19: Break | G19: 0.53125 | H19: Follow-up 1 | I19: 0.53125 | L19: PM | M19: =participants!C16 -> Carlos Quintero N. | N19: =D2 -> 46301 | O19: See schedule | P19: P1 | R19: 0
A20: 0.54166667 | B20: QA (PQA) | C20: 0.54166667 | D20: Break | E20: 0.54166667 | F20: FAR 01 (DAR, TS, PI) | G20: 0.54166667 | H20: Characterize and Create Preliminary Findings | I20: 0.54166667 | J20: Final Findings & Performance Report presentation. | M20: =participants!C17 -> Miguel A. López H. | P20: P2 | S20: 1
A21: 0.55208333 | C21: 0.55208333 | D21: PM1 (RDM, RSK, CAR) | E21: 0.55208333 | G21: 0.55208333 | I21: 0.55208333 | M21: =participants!C18 -> 0 | P21: P3
A22: 0.5625 | C22: 0.5625 | E22: 0.5625 | G22: 0.5625 | I22: 0.5625 | K22: des | L22: FAR01 ENGINEERING | M22: =participants!C19 -> 0 | N22: =F2 -> 46302 | O22: See schedule | P22: P1
A23: 0.57291667 | C23: 0.57291667 | E23: 0.57291667 | G23: 0.57291667 | I23: 0.57291667 | K23: des | M23: =participants!C20 -> Miguel A. López H. | P23: P2 | S23: 0
A24: 0.58333333 | B24: Lunch | C24: 0.58333333 | E24: 0.58333333 | G24: 0.58333333 | I24: 0.58333333 | J24: Lunch | K24: des | M24: =participants!C21 -> 0 | P24: P3
A25: 0.59375 | C25: 0.59375 | E25: 0.59375 | G25: 0.59375 | I25: 0.59375 | K25: dev | M25: =participants!C22 -> 0 | P25: P1
A26: 0.60416667 | C26: 0.60416667 | E26: 0.60416667 | F26: Lunch | G26: 0.60416667 | I26: 0.60416667 | K26: dev | M26: =participants!C23 -> 0 | P26: P1
A27: 0.61458333 | C27: 0.61458333 | D27: Lunch | E27: 0.61458333 | G27: 0.61458333 | I27: 0.61458333 | K27: dev | M27: =participants!C24 -> 0 | P27: P1
A28: 0.625 | C28: 0.625 | E28: 0.625 | G28: 0.625 | H28: Lunch | I28: 0.625 | K28: dev | M28: =participants!C25 -> 0 | P28: P2
A29: 0.63541667 | C29: 0.63541667 | E29: 0.63541667 | G29: 0.63541667 | I29: 0.63541667 | J29: Contingency block | K29: dev | M29: =participants!C26 -> Miguel A. López H. | P29: P2 | S29: 0
A30: 0.64583333 | B30: Evidence Review & Preliminary Findings | C30: 0.64583333 | E30: 0.64583333 | G30: 0.64583333 | I30: 0.64583333 | K30: dev | M30: =participants!C27 -> 0 | P30: P2
A31: 0.65625 | C31: 0.65625 | E31: 0.65625 | G31: 0.65625 | I31: 0.65625 | M31: =participants!C28 -> 0 | P31: P3 | R31: 0
A32: 0.66666667 | C32: 0.66666667 | E32: 0.66666667 | F32: Evidence Review & Preliminary Findings | G32: 0.66666667 | I32: 0.66666667 | M32: =participants!C29 -> 0 | P32: P3 | R32: 0
A33: 0.67708333 | C33: 0.67708333 | D33: Evidence Review & Preliminary Findings | E33: 0.67708333 | G33: 0.67708333 | I33: 0.67708333 | M33: =participants!C30 -> 0 | P33: P3
A34: 0.6875 | C34: 0.6875 | E34: 0.6875 | G34: 0.6875 | H34: Contingency block | I34: 0.6875 | K34: test | L34: FAR02 TESTING | M34: =participants!C31 -> Rodolfo Hernandez | N34: =F2 -> 46302 | O34: See schedule | P34: P1 | R34: 1
A35: 0.69791667 | C35: 0.69791667 | E35: 0.69791667 | G35: 0.69791667 | I35: 0.69791667 | K35: test | M35: =participants!C32 -> 0 | P35: P3
A36: 0.70833333 | C36: 0.70833333 | E36: 0.70833333 | G36: 0.70833333 | I36: 0.70833333 | K36: test | M36: =participants!C33 -> 0 | P36: P3
Q37: =SUM(Q5:Q36) -> 6 | R37: =SUM(R5:R36) -> 1 | S37: =SUM(S5:S36) -> 1 | T37: =SUM(T5:T36) -> 0
M38: Participants and projects marked in blue in this schedule will be the minimum sample review for appraisal per SAMPLING APPROVAL | R38: P1 | S38: P2 | T38: P3
Q39: =SUM(Q37:U37) -> 8
B43: Important Notes: | L43: *Sponsor must attend the opening briefing and the final presentation
...

Sheet MTs
F1: preguntas
B2: MT1 | F2: GOV 2.1, 2.4, 3.1, 3.2
B3: Participants | C3: PAs assigned | F3: II 2.2, 3.1, 3.2, 3.3,
B4: =B13 -> Luis Erick Rodríguez | C4: GOV, II, MPM, PCM, PAD, PQA | F4: MPM 2.1, 3.3, 2.3, 2.4, 3.5
B5: =B14 -> Florencia Vitale | C5: OT, EST, PLAN, MC, RSK, CAR, DAR | F5: PCM 3.1, 3.2, 2.1,3.5, 3.6
B6: MT2 | F6: PAD 3.2, 2.2, 3.3, 2.3, 3.4, 3.6
B7: Participants | C7: PAs assigned | F7: PQA 2.1, 2.2, 3.1, 2.3, 2.4
B8: =B15 -> Rodolfo Alfonso Hernández | C8: CM, RDM, TS, PI, PR, VV
B9: Jesús Sánchez
B12: Team Member Name | C12: Organizational Affiliation | D12: Years of Development Domain Experience | E12: Years of Management Experience
B13: Luis Erick Rodríguez | C13: Four J's Development Tools Latinoamérica.
B14: Florencia Vitale | C14: Four J's Development Tools Latinoamérica.
B15: Rodolfo Alfonso Hernández | C15: Four J's Development Tools Latinoamérica.
B17: Carlos Quintero N. | C17: Four J's Development Tools Latinoamérica.
B19: Team Member Name | C19: Organizational Affiliation | E19: Name | F19: CMMI DEV | G19: Field Experience | H19: Management Experience | I19: High Maturity Experience | J19: Appraisal Responsibilities
B20: Jesus Sanchez | C20: Independent consultant | E20: Jesús Sánchez | F20: V2.0 | G20: =27+1+1+1+1+1 -> 32 | H20: =26+1+1+1+1+1 -> 31 | I20: 11 | J20: SLA
B21: =B13 -> Luis Erick Rodríguez | C21: =C13 -> Four J's Development Tools Latinoamérica. | E21: Type of Domain Experience | F21: High Maturity Concepts | I21: Specific Responsibilities | J21: PAD, PCM, CAR, MPM, MC, RDM, VV, GOV, II
B22: =B14 -> Florencia Vitale | C22: =C14 -> Four J's Development Tools Latinoamérica. | F22: Project Management.
B23: =B15 -> Rodolfo Alfonso Hernández | C23: =C15 -> Four J's Development Tools Latinoamérica. | F23: Test Engineering.
F24: Design Engineering
B25: OU Coordinator | C25: =C17 -> Four J's Development Tools Latinoamérica. | F25: Requirements specification
B26: =B17 -> Carlos Quintero N. | F26: Root Cause analysis specialist
F27: Project planning and management
B28: Sponsor | C28: Oscar Vera | F28: Management experience (including team lead)
F29: Measurement & Analysis
F30: Process quality assurance and improvement
F31: Quantitative management (e.g., Six Sigma)

Sheet projects
A1: Subgroup | B1: Project | C1: EDP Engineering and Developing Products | E1: ENQ Ensuring Quality | I1: IMP Improving Performance | L1: MBR Managing Business Resilience | M1: MWF Managing the Workforce | N1: PMW Planning and Managing Work | Q1: SI Supporting Implementation
C2: PI Product Integration | D2: TS Technical Solution | E2: PQA Process Quality Assurance | F2: PR Peer Reviews | G2: RDM Requirements Development and Management | H2: VV Verification and Validation | I2: MPM Managing Performance and Measurement | J2: PAD Process Asset Development | K2: PCM Process Management | L2: RSK Risk and Opportunity Management | M2: OT Organizational Training | N2: EST Estimating | O2: MC Monitor and Control | P2: PLAN Planning | Q2: CAR Causal Analysis and Resolution | R2: CM Configuration Management | S2: DAR Decision Analysis and Resolution
A3: SG1 | B3: P1- Portability ISSSTE (Required Project) | C3: SE | D3: SE | E3: RS | F3: RS | G3: RS | H3: RS | I3: SE | J3: SI | K3: SI | L3: RS | M3: SI | N3: SE | O3: SE | P3: SE | Q3: RS | R3: ADD | S3: RS
A4: SG2 | B4: P2- Improvements to TG7 | C4: RS | D4: RS | E4: SE | F4: SE | G4: SE | H4: SE | I4: ADD | J4: SI | K4: SI | L4: SE | M4: SI | N4: RS | O4: RS | P4: RS | Q4: SE | R4: SE | S4: SE
B5: CM Staff | C5: SI | D5: SI | E5: SI | F5: SI | G5: SI | H5: SI | I5: SI | J5: SI | K5: SI | L5: SI | M5: SI | N5: SI | O5: SI | P5: SI | Q5: SI | R5: RS | S5: SI
B6: EPG Staff | C6: SI | D6: SI | E6: SI | F6: SI | G6: SI | H6: SI | I6: RS | J6: RS | K6: RS | L6: SI | M6: SI | N6: SI | O6: SI | P6: SI | Q6: SI | R6: SI | S6: SI
B7: OT Staff | C7: SI | D7: SI | E7: SI | F7: SI | G7: SI | H7: SI | I7: SI | J7: SI | K7: SI | L7: SI | M7: RS | N7: SI | O7: SI | P7: SI | Q7: SI | R7: SI | S7: SI
B8: QA Staff | C8: SI | D8: SI | E8: ADD | F8: SI | G8: SI | H8: SI | I8: SI | J8: SI | K8: SI | L8: SI | M8: SI | N8: SI | O8: SI | P8: SI | Q8: SI | R8: SI | S8: SI

Sheet participants
B1: ROLE/ACTIVITY | C1: PARTICIPANTS | G1: Participant's Full Name (required) | H1: Participant's Role (required) | I1: Function (required) | J1: PA | M1: Participant's Full Name (required) | N1: Participant's Role (required) | O1: Function (required) | P1: PA
B2: EGP | C2: =G3 -> Ana L. Fragoso C. | G2: Oscar Vera | H2: SM | I2: OU | J2: GOV, II | M2: Oscar Vera | N2: SM | O2: OU | P2: GOV, II
G3: Ana L. Fragoso C. | H3: EPG | I3: OU | J3: MPM, | M3: Ana L. Fragoso C. | N3: EPG | O3: OU | P3: PCM, PAD, MPM
G4: Florencia Vitale | H4: OT | I4: OU | J4: OT | M4: Karen Ailine Espinoza | N4: EPG | O4: OU | P4: PCM, PAD,
B5: QA (Quality Assurance) | C5: =G5 -> Luis Erick Rodríguez | G5: Luis Erick Rodríguez | H5: QA | I5: OU | J5: PQA | N5: EPG | O5: OU | P5: PCM, PAD, MPM
G6: Carlos Quintero N. | H6: CM | I6: OU | J6: CM | M6: Florencia Vitale | N6: OT | O6: OU | P6: OT
B7: OT | C7: =G4 -> Florencia Vitale | G7: Carlos Quintero N. | H7: PM | I7: P1 | J7: RSK, CAR, DAR | N7: QA | O7: OU | P7: PQA
G8: Miguel A. López H. | H8: PM | I8: P2 | J8: EST, PLAN, MC | M8: Luis Erick Rodríguez | N8: QA | O8: OU | P8: PQA
B9: CM | C9: =G6 -> Carlos Quintero N. | H9: PM | I9: P3 | J9: EST, PLAN, MC, RSK, CAR | M9: Carlos Quintero N. | N9: CM | O9: OU | P9: CM
B10: Sr. Management | C10: =G2 -> Oscar Vera | G10: Carlos Quintero N. | H10: Requirement | I10: P1 | J10: RDM | N10: CM | O10: OU | P10: CM
H11: Requirement | I11: P2 | J11: RDM | M11: Carlos Quintero N. | N11: PM | O11: P1 | P11: EST, PLAN, MC, RSK, CAR
H12: Requirement | I12: P3 | J12: RDM | M12: Miguel A. López H. | N12: PM | O12: P2 | P12: EST, PLAN, MC, RSK, CAR
B13: RDM (Requirements) | C13: =G10 -> Carlos Quintero N. | H13: Designer | I13: P1 | J13: TS, DAR | N13: PM | O13: P3 | P13: EST, PLAN, MC, RSK, CAR
C14: =G11 -> 0 | G14: Miguel A. López H. | H14: Designer | I14: P2 | J14: TS | M14: Carlos Quintero N. | N14: Requirement | O14: P1 | P14: RDM
C15: =G12 -> 0 | H15: Designer | I15: P3 | J15: TS | N15: Requirement , | O15: P2 | P15: RDM
B16: PMO | C16: =G7 -> Carlos Quintero N. | N16: Designer | O16: P1 | P16: TS, DAR
C17: =G8 -> Miguel A. López H. | H17: Engineer | I17: P1 | J17: PI | M17: Miguel A. López H. | N17: Designer | O17: P2 | P17: TS, DAR
C18: =G9 -> 0 | H18: Engineer | I18: P1 | J18: PI | N18: Designer | O18: P3 | P18: TS, DAR
B19: FAR 01 | C19: =G13 -> 0 | D19: P1 | H19: Engineer | I19: P1 | J19: PI | M19: Miguel A. López H. | N19: Developer | O19: P2 | P19: PI, PR
C20: =G14 -> Miguel A. López H. | D20: P2 | G20: Miguel A. López H. | H20: Engineer | I20: P2 | J20: PI, | O20: P1 | P20: PI
C21: =G15 -> 0 | D21: P3 | H21: Engineer | I21: P2 | J21: PI, PR | N21: Engineer | O21: P1, P2, P3 | P21: PI
C22: =G16 -> 0 | D22: P1 | H22: Researcher | I22: P1 | J22: RDM, VV | O22: P2 | P22: PI
C23: =G17 -> 0 | D23: P1 | H23: Researcher | I23: P1 | J23: RDM, VV | N23: Designer | O23: P3 | P23: PI, TS
C24: =G18 -> 0 | D24: P1 | H24: Engineer | I24: P3 | J24: PI | O24: P3 | P24: PI
C25: =G19 -> 0 | D25: P2 | G25: Rodolfo Hernandez | H25: Tester | I25: P1 | J25: VV, PR | O25: P3 | P25: PI
C26: =G20 -> Miguel A. López H. | D26: P2 | H26: Tester | I26: P2 | J26: VV, PR | M26: Rodolfo Hernandez | N26: Tester | O26: P1 | P26: VV, PR
C27: =G21 -> 0 | D27: P2 | H27: Tester | I27: P3 | J27: VV, PR | N27: Tester | O27: P2 | P27: VV, PR
C28: =G22 -> 0 | D28: P3 | N28: Tester | O28: P3 | P28: VV, PR
C29: =G23 -> 0 | D29: P3
C30: =G24 -> 0 | D30: P3
B31: FAR 02 | C31: =G25 -> Rodolfo Hernandez | D31: P1
C32: =G26 -> 0 | D32: P2
C33: =G27 -> 0 | D33: P3

Sheet checklist
B4: Checklist conduct appraisal | C4: Done | F4: Strengths - A type of preliminary or final finding, which is an exemplary or noteworthy implementation of a process that meets the intent and value of a CMMI model practice.
A5: 1 | B5: Sign Sponsor, ATMs and Interpreter CONFIDENTIALITY AND NON-ATTRIBUTION in CAS
A6: 2 | B6: Schedule
A7: 3 | B7: Test conection | F7: Weaknesses - A type of preliminary or final finding, which is an ineffective, or lack of, implementation of one or more processes meet the intent and value of a practice based on verified OE, and applicable across the project(s) and organizational support functions or OU as a whole.
A8: 4 | B8: Script
A9: 5 | B9: Performance report
A10: 6 | B10: Findings template | F10: Improvement Opportunity - A type of preliminary or Final Findings about a particular process that meets the intent and value of a model practice but represents an opportunity where the process could be improved to provide more value.
A11: 7 | B11: ATM pictures in CAS and sponosor verify identity.
A12: 8 | B12: Set of documents in each ATM
A13: 9 | B13: Train ATM: concepts
A14: 10 | B14: Train ATM: caracterization and ratings
A15: 11 | B15: Check the license | F15: Ensure that all Appraisal Team Members (ATMs) have access to a licensed current version of the CMMI model.
