Workbook

Sheet Información del documento
A1: Logo de la empresa
A3: Alcance a nivel proyecto
A6: Historial de versiones
A8: Fecha | B8: Versión | C8: Descripción | D8: Autor
A9: dd/mm/aaaa. | B9: Número de la versión v.v. | C9: Descripción de los cambios realizados en el documento. | D9: Nombre y apellido.
A10: 27/07/2026 | B10: 1.1 | C10: Se registra la auditoría real al proyecto Portabilidad ISSSTE-IMSS (fases de inicio, ejecución y cierre) realizada por Miguel A. López Hernández, con varios hallazgos genuinos sobre el cierre formal pendiente; se corrige "está hoja". | D10: Carlos Quintero N.
A11: 27/07/2026 | B11: 1.2 | C11: Se corrige el criterio "¿Se realiza una revisión entre pares del enunciado de trabajo?": confirmado mediante evidencia de Jira (tarea IP-15) que sí se realizó; se cambia de "No" a "Sí". | D11: Carlos Quintero N.
A14: Si se tiene un sistema de gestión de versiones eliminar esta hoja.

Sheet 1.-Resumen general
A1: Datos generales
A2: Proyecto: | B2: Portabilidad de Derechos Pensionarios entre ISSSTE e IMSS
A3: Nombre del Líder de Proyecto | B3: Carlos Quintero Nava
A4: Fase del proyecto: | B4: Cierre (Entrega Final v2.0)
A6: Resumen general
A7: Nombre de la auditoría | B7: Procedimientos | C7: Fecha de la auditoría | D7: % apego | E7: Auditor | F7: Observaciones
A8: Inicio | B8: Estimación | C8: ='2.-Auditoría_inicio'!D1 | D8: ='2.-Auditoría_inicio'!G2 | E8: ='2.-Auditoría_inicio'!D2
B9: Planeación | C9: ='2.-Auditoría_inicio'!D4 | D9: ='2.-Auditoría_inicio'!G5 | E9: ='2.-Auditoría_inicio'!D5
B10: Gestión de requisitos | C10: ='2.-Auditoría_inicio'!D7 | D10: ='2.-Auditoría_inicio'!G8 | E10: ='2.-Auditoría_inicio'!D8
A11: Ejecución 1 | B11: Diseño de software | C11: ='3.1-Auditoría_ejecución'!D1 | D11: ='3.1-Auditoría_ejecución'!G2 | E11: ='3.1-Auditoría_ejecución'!D2
B12: Construcción | C12: ='3.1-Auditoría_ejecución'!D4 | D12: ='3.1-Auditoría_ejecución'!G5 | E12: ='3.1-Auditoría_ejecución'!D5
B13: Revisión por pares | C13: ='3.1-Auditoría_ejecución'!D7 | D13: ='3.1-Auditoría_ejecución'!G8 | E13: ='3.1-Auditoría_ejecución'!D8
A14: Ejecución 2 | B14: Diseño de software | C14: ='3.2-Auditoría_ejecución 2vuelta'!D1 | D14: ='3.2-Auditoría_ejecución 2vuelta'!G2 | E14: ='3.2-Auditoría_ejecución 2vuelta'!D2
B15: Construcción | C15: ='3.2-Auditoría_ejecución 2vuelta'!D4 | D15: ='3.2-Auditoría_ejecución 2vuelta'!G5 | E15: ='3.2-Auditoría_ejecución 2vuelta'!D5
B16: Revisión por pares | C16: ='3.2-Auditoría_ejecución 2vuelta'!D7 | D16: ='3.2-Auditoría_ejecución 2vuelta'!G8 | E16: ='3.2-Auditoría_ejecución 2vuelta'!D8
A17: Ejecución 3 | B17: Diseño de software | C17: ='3.3-Auditoría_ejecución 3vuelta'!D1 | D17: ='3.3-Auditoría_ejecución 3vuelta'!G2 | E17: ='3.3-Auditoría_ejecución 3vuelta'!D2
B18: Construcción | C18: ='3.3-Auditoría_ejecución 3vuelta'!D4 | D18: ='3.3-Auditoría_ejecución 3vuelta'!G5 | E18: ='3.3-Auditoría_ejecución 3vuelta'!D5
B19: Revisión por pares | C19: ='3.3-Auditoría_ejecución 3vuelta'!D7 | D19: ='3.3-Auditoría_ejecución 3vuelta'!G8 | E19: ='3.3-Auditoría_ejecución 3vuelta'!D8
A20: Cierre | B20: Pruebas | C20: ='4.-Auditoría cierre'!D1 | D20: ='4.-Auditoría cierre'!G2 | E20: ='4.-Auditoría cierre'!D2
B21: Entrega del producto | C21: ='4.-Auditoría cierre'!D4 | D21: ='4.-Auditoría cierre'!G5 | E21: ='4.-Auditoría cierre'!D5
B22: Cierre | C22: ='4.-Auditoría cierre'!D7 | D22: ='4.-Auditoría cierre'!G8 | E22: ='4.-Auditoría cierre'!D8
A23: Gestión de cambios | B23: Monitoreo | C23: ='5.-Auditoría_Gestión de cambios'!D1 | D23: ='5.-Auditoría_Gestión de cambios'!G2 | E23: ='5.-Auditoría_Gestión de cambios'!D2

Sheet 2.-Auditoría_inicio
A1: Estimación | C1: Fecha auditoría | D1: 25/07/2026 | E1: Preguntas aprobadas | G1: =COUNTA(D14:D23)+COUNTA(F14:F23)
C2: Auditor | D2: Miguel A. López Hernández | E2: % de apego | G2: =G1/COUNT(A14:A23)
C3: Auditado | D3: Carlos Quintero Nava
A4: Planeación | C4: Fecha auditoría | D4: 25/07/2026 | E4: Preguntas aprobadas | G4: =COUNTA(D25:D35)+COUNTA(F25:F35)
C5: Auditor | D5: Miguel A. López Hernández | E5: % de apego | G5: =G4/COUNT(A25:A35)
C6: Auditado | D6: Carlos Quintero Nava
A7: Gestión de requisitos | C7: Fecha auditoría | D7: 25/07/2026 | E7: Preguntas aprobadas | G7: =COUNTA(D38:D47)+COUNTA(F38:F47)
C8: Auditor | D8: Miguel A. López Hernández | E8: % de apego | G8: =G7/COUNT(A38:A47)
C9: Auditado | D9: Carlos Quintero Nava
A10: Auditoria de proyecto
A11: No. | B11: Verificación | D11: Condiciones | G11: Observaciones
B12: Criterio a verificar | D12: Sí | E12: No | F12: No aplica
A13: Estimaciones
A14: 1 | B14: ¿Se revisa el alcance y requisitos con ayuda del enunciado de trabajo? | D14: X
A15: 2 | B15: ¿Se utilizan históricos para realizar estimaciones? | D15: X
A16: 3 | B16: ¿Los históricos presentan la siguiente información Dominio de la aplicación Dominio de la tecnología Complejidad del proyecto Cantidad y nivel de conocimiento de las personas? | E16: X | G16: El histórico (RG-Estimación) no desglosa explícitamente las 4 dimensiones solicitadas (dominio de aplicación, tecnología, complejidad, conocimiento del equipo).
A17: 4 | B17: ¿Se estimó el tamaño con un método establecido por la organización? | D17: X
A18: 5 | B18: ¿Se estimó el esfuerzo con un método establecido por la organización? | D18: X
A19: 6 | B19: ¿Se estimó el tiempo con un método establecido por la organización? | D19: X
A20: 7 | B20: ¿El costo incluye la evaluación de recursos humanos y materiales necesarios para llevar a cabo el proyecto? | D20: X
A21: 8 | B21: ¿Se identificaron riesgos? | D21: X
A22: 3 | B22: ¿Se utiliza una herramienta (Plantilla) para estimar? | D22: X
A23: 10 | B23: ¿Existen registros de las reuniones con el equipo estimador? | D23: X
A24: Gestión de requisitos
A25: 1 | B25: ¿Se identificó quiénes son proveedores de requisitos? | D25: X
A26: 2 | B26: ¿Se utilizaron técnicas de levantamiento de requisitos establecidas por la organización? | D26: X
A27: 3 | B27: ¿Se identificaron claramente NERI´s? | D27: X
A28: 4 | B28: ¿Se cuenta con un Enunciado de trabajo que mencione Requisitos funcionales y no funcionales e interfaces de manera clara y sin ambigüedades? | D28: X
A29: 5 | B29: ¿Se revisa el enunciado de trabajo con los stakeholder para validar que los requisitos sean todos y estén correctos? | D29: X
A30: 6 | B30: ¿Se realiza una revisión entre pares del enunciado de trabajo? | D30: X
A31: 7 | B31: ¿Se validaron los requisitos utilizando el documento validación de requisitos? | D31: X
A32: 8 | B32: ¿Se encuentran estos documentos de insumo y validación almacenados correctamente en el repositorio? | D32: X
A33: 9 | B33: ¿Se puede comenzar el manual de usuario una vez que tenemos requisitos e historias de usuario o casos de uso? | D33: X
A34: 10 | B34: ¿Se realizo una auditoria de configuración a la especificación de requisitos? | D34: X
A35: 11 | B35: ¿Se Comunicaron los resultados a las personas interesadas? | D35: X
A36: Planeación
A37: 1 | B37: ¿Existe un repositorio del proyecto?
A38: 1 | B38: ¿Se revisó el alcance del proyecto en el enunciado de trabajo para la planeación del proyecto? | D38: X
A39: 2 | B39: ¿Algunos de los Stakeholders identificados en el plan cumplen con los siguientes roles de recepción, aceptación e implementación del producto de software? | D39: X
A40: 3 | B40: ¿Están registrados los entregables que deben entregarse en el plan del proyecto? | D40: X
...

Sheet 3.1-Auditoría_ejecución
A1: Diseño de software | C1: Fecha auditoría | D1: 26/07/2026 | E1: Preguntas aprobadas | G1: =COUNTA(D14:D24)+COUNTA(F14:F24)
C2: Auditor | D2: Miguel A. López Hernández | E2: % de apego | G2: =G1/COUNT(A14:A24)
C3: Auditado | D3: Carlos Quintero Nava
A4: Construcción | C4: Fecha auditoría | D4: 26/07/2026 | E4: Preguntas aprobadas | G4: =COUNTA(D26:D34)+COUNTA(F26:F34)
C5: Auditor | D5: Miguel A. López Hernández | E5: % de apego | G5: =G4/COUNT(A26:A34)
C6: Auditado | D6: Carlos Quintero Nava
A7: Revisión entre pares | C7: Fecha auditoría | D7: 26/07/2026 | E7: Preguntas aprobadas | G7: =COUNTA(D36:D41)+COUNTA(F36:F41)
C8: Auditor | D8: Miguel A. López Hernández | E8: % de apego | G8: =G7/COUNT(A36:A41)
C9: Auditado | D9: Carlos Quintero Nava
A10: Auditoria de proyecto / Ejecución 1
A11: No. | B11: Verificación | D11: Condiciones | G11: Observaciones
B12: Criterio a verificar | D12: Sí | E12: No | F12: No aplica
A13: Diseño de software
A14: 1 | B14: ¿Cuándo se evalúa y seleccionan alternativas para abordar requisitos se registran los resultados acordados? | D14: X
A15: 2 | B15: ¿Al definir la arquitectura se consideraron los siguientes aspectos: -Requisitos fun. Y no fun. Del sistema, necesidades de usuario, rendimiento, escalabilidad y disponibilidad -Diseño a alto nivel de estructura general, componentes, módulos y subsistemas -Patrones arquitectónicos apropiados -Tecnologías y plataformas que se utilizarán en el desarrollo -Manejo de excepciones? | D15: X
A16: 3 | B16: ¿Se tiene un diseño de interfaces de acuerdo con el doc. Especificación de requisitos? | D16: X
A17: 4 | B17: ¿El diseño detallado especifica la implementación de los componentes y módulos del sistema incluyendo interfaces, interacciones y flujo de datos? | D17: X
A18: 5 | B18: ¿Se realizó auditoria de configuración al documento de diseño de software? | E18: X | G18: La auditoría de configuración de documentación cubrió la Especificación de requisitos; no se realizó una auditoría específica al documento de Diseño de software.
A19: 6 | B19: ¿Se comunicó a las personas interesadas los resultados de la auditoria al documento diseño de software? | D19: X
A20: 7 | B20: ¿El documento de diseño de software tiene línea base actualizada? | D20: X
A21: 8 | B21: ¿Se diseñaron casos de prueba? | D21: X
A22: 9 | B22: ¿El manual de operaciones y de mantenimiento fueron evaluados en revisión entre pares? | D22: X
A23: 10 | B23: ¿Se realizó auditoría al manual de operaciones y de mantenimiento? | E23: X | G23: No se realizó una auditoría de configuración específica a los manuales de operaciones y mantenimiento.
A24: 11 | B24: ¿Los manuales tienen línea base actualizada? | D24: X
A25: Construcción
A26: 1 | B26: ¿Se tomaron en cuenta los estándares de codificación y la secuencia de integración al codificar componentes? | D26: X
A27: 2 | B27: ¿Se realizaron pruebas unitarias a cada componente codificado? | D27: X
A28: 3 | B28: ¿Se utilizó el checklist de integración para preparar la integración? | D28: X
A29: 4 | B29: ¿Se utilizo el documento estrategia de integración para llevar a cabo la integración de componentes? | D29: X
A30: 5 | B30: ¿Se realizaron pruebas de integración? | D30: X
A31: 6 | B31: ¿Se informo a las personas interesadas el resultado de estas pruebas? | D31: X
A32: 7 | B32: ¿Se registraron los resultados de las pruebas? | D32: X
A33: 8 | B33: ¿En caso de tener defectos, se registraron y se les dio seguimiento en el documento gestión de pruebas en la hoja pruebas internas? | E33: X | G33: El defecto real (DEF-01) se registró en FT-Gestión de incidencias, no en la hoja "pruebas internas" del documento de gestión de pruebas como establece el criterio.
A34: 9 | B34: ¿Se tiene versión de software? | D34: X
A35: Revisión por pares
A36: 1 | B36: ¿La lista de verificación se encuentra actualizada? | D36: X
A37: 2 | B37: ¿La lista de verificación contiene todos los elementos requeridos para la revisión del producto de trabajo específico? | D37: X
A38: 3 | B38: ¿Los resultados de la revisión entre pares se encuentran en el checklist? | D38: X
A39: 4 | B39: ¿El correo que comparte los resultados de la revisión contiene el enlace al documento (Checklist)? | D39: X
A40: 5 | B40: ¿En caso de tener defectos, se menciona la fecha para resolver defecto? | D40: X
...

Sheet 3.2-Auditoría_ejecución 2vuelta
A1: Diseño de software | C1: Fecha auditoría | D1: dd/mm/aaaa | E1: Preguntas aprobadas | G1: =COUNTA(D14:D24)+COUNTA(F14:F24)
C2: Auditor | D2: Nombre y apellido | E2: % de apego | G2: =G1/COUNT(A14:A24)
C3: Auditado | D3: Nombre y apellido
A4: Construcción | C4: Fecha auditoría | D4: dd/mm/aaaa | E4: Preguntas aprobadas | G4: =COUNTA(D26:D34)+COUNTA(F26:F34)
C5: Auditor | D5: Nombre y apellido | E5: % de apego | G5: =G4/COUNT(A26:A34)
C6: Auditado | D6: Nombre y apellido
A7: Revisión entre pares | C7: Fecha auditoría | D7: dd/mm/aaaa | E7: Preguntas aprobadas | G7: =COUNTA(D36:D41)+COUNTA(F36:F41)
C8: Auditor | D8: Nombre y apellido | E8: % de apego | G8: =G7/COUNT(A36:A41)
C9: Auditado | D9: Nombre y apellido
A10: Auditoria de proyecto / Ejecución 1
A11: No. | B11: Verificación | D11: Condiciones | G11: Observaciones
B12: Criterio a verificar | D12: Sí | E12: No | F12: No aplica
A13: Diseño de software
A14: 1 | B14: ¿Cuándo se evalúa y seleccionan alternativas para abordar requisitos se registran los resultados acordados?
A15: 2 | B15: ¿Al definir la arquitectura se consideraron los siguientes aspectos: -Requisitos fun. Y no fun. Del sistema, necesidades de usuario, rendimiento, escalabilidad y disponibilidad -Diseño a alto nivel de estructura general, componentes, módulos y subsistemas -Patrones arquitectónicos apropiados -Tecnologías y plataformas que se utilizarán en el desarrollo -Manejo de excepciones?
A16: 3 | B16: ¿Se tiene un diseño de interfaces de acuerdo con el doc. Especificación de requisitos?
A17: 4 | B17: ¿El diseño detallado especifica la implementación de los componentes y módulos del sistema incluyendo interfaces, interacciones y flujo de datos?
A18: 5 | B18: ¿Se realizó auditoria de configuración al documento de diseño de software?
A19: 6 | B19: ¿Se comunicó a las personas interesadas los resultados de la auditoria al documento diseño de software?
A20: 7 | B20: ¿El documento de diseño de software tiene línea base actualizada?
A21: 8 | B21: ¿Se diseñaron casos de prueba?
A22: 9 | B22: ¿El manual de operaciones y de mantenimiento fueron evaluados en revisión entre pares?
A23: 10 | B23: ¿Se realizó auditoría al manual de operaciones y de mantenimiento?
A24: 11 | B24: ¿Los manuales tienen línea base actualizada?
A25: Construcción
A26: 1 | B26: ¿Se tomaron en cuenta los estándares de codificación y la secuencia de integración al codificar componentes?
A27: 2 | B27: ¿Se realizaron pruebas unitarias a cada componente codificado?
A28: 3 | B28: ¿Se utilizó el checklist de integración para preparar la integración?
A29: 4 | B29: ¿Se utilizo el documento estrategia de integración para llevar a cabo la integración de componentes?
A30: 5 | B30: ¿Se realizaron pruebas de integración?
A31: 6 | B31: ¿Se informo a las personas interesadas el resultado de estas pruebas?
A32: 7 | B32: ¿Se registraron los resultados de las pruebas?
A33: 8 | B33: ¿En caso de tener defectos, se registraron y se les dio seguimiento en el documento gestión de pruebas en la hoja pruebas internas?
A34: 9 | B34: ¿Se tiene versión de software?
A35: Revisión por pares
A36: 1 | B36: ¿La lista de verificación se encuentra actualizada?
A37: 2 | B37: ¿La lista de verificación contiene todos los elementos requeridos para la revisión del producto de trabajo específico?
A38: 3 | B38: ¿Los resultados de la revisión entre pares se encuentran en el checklist?
A39: 4 | B39: ¿El correo que comparte los resultados de la revisión contiene el enlace al documento (Checklist)?
A40: 5 | B40: ¿En caso de tener defectos, se menciona la fecha para resolver defecto?
...

Sheet 3.3-Auditoría_ejecución 3vuelta
A1: Diseño de software | C1: Fecha auditoría | D1: dd/mm/aaaa | E1: Preguntas aprobadas | G1: =COUNTA(D14:D24)+COUNTA(F14:F24)
C2: Auditor | D2: Nombre y apellido | E2: % de apego | G2: =G1/COUNT(A14:A24)
C3: Auditado | D3: Nombre y apellido
A4: Construcción | C4: Fecha auditoría | D4: dd/mm/aaaa | E4: Preguntas aprobadas | G4: =COUNTA(D26:D34)+COUNTA(F26:F34)
C5: Auditor | D5: Nombre y apellido | E5: % de apego | G5: =G4/COUNT(A26:A34)
C6: Auditado | D6: Nombre y apellido
A7: Revisión entre pares | C7: Fecha auditoría | D7: dd/mm/aaaa | E7: Preguntas aprobadas | G7: =COUNTA(D36:D41)+COUNTA(F36:F41)
C8: Auditor | D8: Nombre y apellido | E8: % de apego | G8: =G7/COUNT(A36:A41)
C9: Auditado | D9: Nombre y apellido
A10: Auditoria de proyecto / Ejecución 1
A11: No. | B11: Verificación | D11: Condiciones | G11: Observaciones
B12: Criterio a verificar | D12: Sí | E12: No | F12: No aplica
A13: Diseño de software
A14: 1 | B14: ¿Cuándo se evalúa y seleccionan alternativas para abordar requisitos se registran los resultados acordados?
A15: 2 | B15: ¿Al definir la arquitectura se consideraron los siguientes aspectos: -Requisitos fun. Y no fun. Del sistema, necesidades de usuario, rendimiento, escalabilidad y disponibilidad -Diseño a alto nivel de estructura general, componentes, módulos y subsistemas -Patrones arquitectónicos apropiados -Tecnologías y plataformas que se utilizarán en el desarrollo -Manejo de excepciones?
A16: 3 | B16: ¿Se tiene un diseño de interfaces de acuerdo con el doc. Especificación de requisitos?
A17: 4 | B17: ¿El diseño detallado especifica la implementación de los componentes y módulos del sistema incluyendo interfaces, interacciones y flujo de datos?
A18: 5 | B18: ¿Se realizó auditoria de configuración al documento de diseño de software?
A19: 6 | B19: ¿Se comunicó a las personas interesadas los resultados de la auditoria al documento diseño de software?
A20: 7 | B20: ¿El documento de diseño de software tiene línea base actualizada?
A21: 8 | B21: ¿Se diseñaron casos de prueba?
A22: 9 | B22: ¿El manual de operaciones y de mantenimiento fueron evaluados en revisión entre pares?
A23: 10 | B23: ¿Se realizó auditoría al manual de operaciones y de mantenimiento?
A24: 11 | B24: ¿Los manuales tienen línea base actualizada?
A25: Construcción
A26: 1 | B26: ¿Se tomaron en cuenta los estándares de codificación y la secuencia de integración al codificar componentes?
A27: 2 | B27: ¿Se realizaron pruebas unitarias a cada componente codificado?
A28: 3 | B28: ¿Se utilizó el checklist de integración para preparar la integración?
A29: 4 | B29: ¿Se utilizo el documento estrategia de integración para llevar a cabo la integración de componentes?
A30: 5 | B30: ¿Se realizaron pruebas de integración?
A31: 6 | B31: ¿Se informo a las personas interesadas el resultado de estas pruebas?
A32: 7 | B32: ¿Se registraron los resultados de las pruebas?
A33: 8 | B33: ¿En caso de tener defectos, se registraron y se les dio seguimiento en el documento gestión de pruebas en la hoja pruebas internas?
A34: 9 | B34: ¿Se tiene versión de software?
A35: Revisión por pares
A36: 1 | B36: ¿La lista de verificación se encuentra actualizada?
A37: 2 | B37: ¿La lista de verificación contiene todos los elementos requeridos para la revisión del producto de trabajo específico?
A38: 3 | B38: ¿Los resultados de la revisión entre pares se encuentran en el checklist?
A39: 4 | B39: ¿El correo que comparte los resultados de la revisión contiene el enlace al documento (Checklist)?
A40: 5 | B40: ¿En caso de tener defectos, se menciona la fecha para resolver defecto?
...

Sheet 4.-Auditoría cierre
A1: Pruebas | C1: Fecha auditoría | D1: 27/07/2026 | E1: Preguntas aprobadas | G1: =COUNTA(D14:D24)+COUNTA(F14:F24)
C2: Auditor | D2: Miguel A. López Hernández | E2: % de apego | G2: =G1/COUNT(A14:A24)
C3: Auditado | D3: Carlos Quintero Nava
A4: Entrega de producto | C4: Fecha auditoría | D4: 27/07/2026 | E4: Preguntas aprobadas | G4: =COUNTA(D28:D35)+COUNTA(F28:F35)
C5: Auditor | D5: Miguel A. López Hernández | E5: % de apego | G5: =G4/COUNT(A28:A35)
C6: Auditado | D6: Carlos Quintero Nava
A7: Cierre | C7: Fecha auditoría | D7: 27/07/2026 | E7: Preguntas aprobadas | G7: =COUNTA(D37:D43)+COUNTA(F37:F43)
C8: Auditor | D8: Miguel A. López Hernández | E8: % de apego | G8: =G7/COUNT(A37:A43)
C9: Auditado | D9: Carlos Quintero Nava
A10: Auditoria de proyecto / Ejecución 2
A11: No. | B11: Verificación | D11: Condiciones | G11: Observaciones
B12: Criterio a verificar | D12: Sí | E12: No | F12: No aplica
A13: Pruebas
A14: 1 | B14: ¿Se preparó el ambiente de pruebas de acuerdo con el plan de pruebas establecido por la organización? | D14: X
A15: 2 | B15: ¿Se registrarón los resultados de la ejecución de pruebas en el documento Gestión de pruebas en la hoja de pruebas internas? | D15: X
A16: 3 | B16: ¿Los defectos encontrados se registrarón en el docuemnto Gestión de incidencias en la hoja de defectos ? | D16: X
A17: 4 | B17: Para comunicar los resultdos, ¿Se compartierón por correo electrónico adjuntando el enlace al docuento Gestión de incidencias? | D17: X
A18: 5 | B18: ¿Se asignó responsable de resolver el defecto y la fecha en que tiene que quedar resuleto el refecto? | D18: X
A19: 6 | B19: ¿El responsable de corregir defectos informó el tiempo en horas qué le dedicó a resolver el defecto? | D19: X
A20: 7 | B20: ¿En el docuemnto Gestión de incidencias se actualizo el estado del defecto y la fecha real en que se corrigió el defecto? | D20: X
A21: 8 | B21: ¿El manual de usuario contiene imágenes de las funcionalidades del software? | E21: X | G21: El manual de usuario conserva las 2 imágenes ilustrativas genéricas de la plantilla original; no se cuenta con capturas reales de los portales SINAVID-OV/SIPE-AV.
A22: 9 | B22: ¿Se realizó revisión entre pares? | D22: X
A23: 10 | B23: ¿Se realizó la auditoria de configuración al manual de usuario con la lista de verificación que se encuentra en el documento Auditoria de configuración docuemntación? | E23: X | G23: No se realizó una auditoría de configuración específica al manual de usuario; la auditoría cubrió la Especificación de requisitos.
A24: 11 | B24: ¿El correo electrónico comunica los resultados de la auditoria de configuración e incluye el enlace al documento que detalla: La desviación (es) indentificada(as), y la fecha de resolución? | F24: X | G24: No aplica, dado que no se realizó la auditoría de configuración al manual de usuario (ver hallazgo anterior).
A25: 12 | B25: ¿Sí la línea base fue aprobada, se informo por correo electrónico? | D25: X
A26: 13 | B26: ¿El manual de usuario fue etiquetado de acuerdo a las directrices del DZ-Plan de gestión de la configuración? | D26: X
A27: Entrega de producto
A28: 1 | B28: Se prepararón los elementos antes la entrega al cliente? Como manuales, arquitectura de sotfware, formularios de entrega, criterios de aceptación, Así como lo necesario para instalar el software en los equipos del cliente. | D28: X
A29: 2 | B29: ¿Mientras un técnico participa en la validación de criterios, el líder del proyecto otorgo los entregables? | D29: X
A30: 3 | B30: Se realizó la isntalación del software de acuerdo al plan de transición? | D30: X
A31: 4 | B31: ¿Se realizarón pruebas para revisar el cumplimiento de los criterios de aceptación en el docuemnto formulario de entrega? | E31: X | G31: No se cuenta con un formulario de entrega construido para este proyecto.
A32: 5 | B32: En caso de incidencias, ¿Se registrarón en el docuemnto de Gestión de incidencias? | D32: X
A33: 6 | B33: ¿Se revisó que las incidencias estuvieran dentro del alcance del proyecto? | D33: X
A34: 7 | B34: ¿Se asigno a un desarrollador para solucionar la falla en el código? | D34: X
A35: 8 | B35: Una vez que el producto funciona correctamente y de acuerdo con los criterios de aceptación ¿El cliente firmó el formulario de entrega? | E35: X | G35: No aplica firma del cliente, dado que no existe el formulario de entrega (ver hallazgo anterior).
A36: Cierre
A37: 1 | B37: ¿Se reviso que todos los documentos de información del proyecto se encuentren actualizados a la ultima versión en el repositorio? | D37: X
A38: 2 | B38: Se verificó el cumplimiento del contrato con el cliente y los proveedores ? | D38: X
A39: 3 | B39: En caso de identificar cuestiones pendientes o abiertas ¿se establecierón fechas para su conclución? | D39: X
A40: 4 | B40: ¿Se identificarón y registrarón lecciones aprendias con el equipo de trabajo del proyecto? | E40: X | G40: No se ha realizado una reunión formal de lecciones aprendidas para este proyecto.
...

Sheet 5.-Auditoría_Gestión de cambios
A1: Monitoreo | C1: Fecha auditoría | D1: 27/07/2026 | E1: Preguntas aprobadas | G1: =COUNTA(D8:D15)+COUNTA(F8:F15)
C2: Auditor | D2: Miguel A. López Hernández | E2: % de apego | G2: =G1/COUNT(A8:A15)
C3: Auditado | D3: Carlos Quintero Nava
A4: Auditoria de gestión de cambios
A5: No. | B5: Verificación | D5: Condiciones | G5: Observaciones
B6: Criterio a verificar | D6: Sí | E6: No | F6: No aplica
A7: Monitoreo
A8: 1 | B8: ¿La petición de cambios se solicita a través de un formulario de solicitud de cambios con todos los campos requeridos completos? | D8: X
A9: 2 | B9: ¿Se convocó al comité para analizar la(s) solicitud(es)? | D9: X
A10: 3 | B10: ¿Se asignó el cambio solicitado a alguna de las categorías; Mejora, Modificación o Error? | D10: X
A11: 4 | B11: ¿Se evaluó el impacto en las siguientes aspectos; En el producto de software Elementos de configuración Términos de tiempo, esfuerzo y costo? | D11: X
A12: 5 | B12: ¿Se identificaron y evaluaron los riesgos asociados con la implementación del cambio? | E12: X | G12: No se documentó un análisis de riesgos específico para la implementación del cambio CR-01, más allá del análisis de alternativas.
A13: 6 | B13: ¿Se registró la respuesta al cambio en el documento Concentrado de control de cambios? | D13: X
A14: 7 | B14: ¿Se presentó al cliente el tiempo y el costo que implica realizar el cambio solicitado? | D14: X
A15: 8 | B15: ¿Se actualizó el plan de proyecto con las actividades que implican el cambio aprobado? | E15: X | G15: El plan de proyecto no se actualizó explícitamente para reflejar las actividades de la habilitación de la re-portabilidad.
